Internal Server Error: /hospitalisation/generale
Traceback (most recent call last):
  File "/Users/ogahserge/Documents/smitci/venv/lib/python3.9/site-packages/django/contrib/sessions/backends/base.py", line 187, in _get_session
    return self._session_cache
AttributeError: 'SessionStore' object has no attribute '_session_cache'

During handling of the above exception, another exception occurred:

Traceback (most recent call last):
  File "/Users/ogahserge/Documents/smitci/venv/lib/python3.9/site-packages/django/db/backends/utils.py", line 89, in _execute
    return self.cursor.execute(sql, params)
psycopg2.errors.UndefinedTable: relation "django_session" does not exist
LINE 1: ...ession_data", "django_session"."expire_date" FROM "django_se...
                                                             ^


The above exception was the direct cause of the following exception:

Traceback (most recent call last):
  File "/Users/ogahserge/Documents/smitci/venv/lib/python3.9/site-packages/asgiref/sync.py", line 518, in thread_handler
    raise exc_info[1]
  File "/Users/ogahserge/Documents/smitci/venv/lib/python3.9/site-packages/django/core/handlers/exception.py", line 42, in inner
    response = await get_response(request)
  File "/Users/ogahserge/Documents/smitci/venv/lib/python3.9/site-packages/django/core/handlers/base.py", line 253, in _get_response_async
    response = await wrapped_callback(
  File "/Users/ogahserge/Documents/smitci/venv/lib/python3.9/site-packages/asgiref/sync.py", line 468, in __call__
    ret = await asyncio.shield(exec_coro)
  File "/Applications/Xcode.app/Contents/Developer/Library/Frameworks/Python3.framework/Versions/3.9/lib/python3.9/concurrent/futures/thread.py", line 52, in run
    result = self.fn(*self.args, **self.kwargs)
  File "/Users/ogahserge/Documents/smitci/venv/lib/python3.9/site-packages/asgiref/sync.py", line 522, in thread_handler
    return func(*args, **kwargs)
  File "/Users/ogahserge/Documents/smitci/venv/lib/python3.9/site-packages/django/views/generic/base.py", line 104, in view
    return self.dispatch(request, *args, **kwargs)
  File "/Users/ogahserge/Documents/smitci/venv/lib/python3.9/site-packages/django/contrib/auth/mixins.py", line 71, in dispatch
    if not request.user.is_authenticated:
  File "/Users/ogahserge/Documents/smitci/venv/lib/python3.9/site-packages/django/utils/functional.py", line 266, in inner
    self._setup()
  File "/Users/ogahserge/Documents/smitci/venv/lib/python3.9/site-packages/django/utils/functional.py", line 419, in _setup
    self._wrapped = self._setupfunc()
  File "/Users/ogahserge/Documents/smitci/venv/lib/python3.9/site-packages/django/contrib/auth/middleware.py", line 25, in <lambda>
    request.user = SimpleLazyObject(lambda: get_user(request))
  File "/Users/ogahserge/Documents/smitci/venv/lib/python3.9/site-packages/django/contrib/auth/middleware.py", line 11, in get_user
    request._cached_user = auth.get_user(request)
  File "/Users/ogahserge/Documents/smitci/venv/lib/python3.9/site-packages/django/contrib/auth/__init__.py", line 191, in get_user
    user_id = _get_user_session_key(request)
  File "/Users/ogahserge/Documents/smitci/venv/lib/python3.9/site-packages/django/contrib/auth/__init__.py", line 60, in _get_user_session_key
    return get_user_model()._meta.pk.to_python(request.session[SESSION_KEY])
  File "/Users/ogahserge/Documents/smitci/venv/lib/python3.9/site-packages/django/contrib/sessions/backends/base.py", line 53, in __getitem__
    return self._session[key]
  File "/Users/ogahserge/Documents/smitci/venv/lib/python3.9/site-packages/django/contrib/sessions/backends/base.py", line 192, in _get_session
    self._session_cache = self.load()
  File "/Users/ogahserge/Documents/smitci/venv/lib/python3.9/site-packages/django/contrib/sessions/backends/db.py", line 42, in load
    s = self._get_session_from_db()
  File "/Users/ogahserge/Documents/smitci/venv/lib/python3.9/site-packages/django/contrib/sessions/backends/db.py", line 32, in _get_session_from_db
    return self.model.objects.get(
  File "/Users/ogahserge/Documents/smitci/venv/lib/python3.9/site-packages/django/db/models/manager.py", line 87, in manager_method
    return getattr(self.get_queryset(), name)(*args, **kwargs)
  File "/Users/ogahserge/Documents/smitci/venv/lib/python3.9/site-packages/django/db/models/query.py", line 633, in get
    num = len(clone)
  File "/Users/ogahserge/Documents/smitci/venv/lib/python3.9/site-packages/django/db/models/query.py", line 380, in __len__
    self._fetch_all()
  File "/Users/ogahserge/Documents/smitci/venv/lib/python3.9/site-packages/django/db/models/query.py", line 1881, in _fetch_all
    self._result_cache = list(self._iterable_class(self))
  File "/Users/ogahserge/Documents/smitci/venv/lib/python3.9/site-packages/django/db/models/query.py", line 91, in __iter__
    results = compiler.execute_sql(
  File "/Users/ogahserge/Documents/smitci/venv/lib/python3.9/site-packages/django/db/models/sql/compiler.py", line 1562, in execute_sql
    cursor.execute(sql, params)
  File "/Users/ogahserge/Documents/smitci/venv/lib/python3.9/site-packages/django/db/backends/utils.py", line 102, in execute
    return super().execute(sql, params)
  File "/Users/ogahserge/Documents/smitci/venv/lib/python3.9/site-packages/django/db/backends/utils.py", line 67, in execute
    return self._execute_with_wrappers(
  File "/Users/ogahserge/Documents/smitci/venv/lib/python3.9/site-packages/django/db/backends/utils.py", line 80, in _execute_with_wrappers
    return executor(sql, params, many, context)
  File "/Users/ogahserge/Documents/smitci/venv/lib/python3.9/site-packages/django/db/backends/utils.py", line 89, in _execute
    return self.cursor.execute(sql, params)
  File "/Users/ogahserge/Documents/smitci/venv/lib/python3.9/site-packages/django/db/utils.py", line 91, in __exit__
    raise dj_exc_value.with_traceback(traceback) from exc_value
  File "/Users/ogahserge/Documents/smitci/venv/lib/python3.9/site-packages/django/db/backends/utils.py", line 89, in _execute
    return self.cursor.execute(sql, params)
django.db.utils.ProgrammingError: relation "django_session" does not exist
LINE 1: ...ession_data", "django_session"."expire_date" FROM "django_se...
                                                             ^

[35;1mHTTP GET /hospitalisation/generale 500 [0.18, 127.0.0.1:58946][0m
Internal Server Error: /hospitalisation/generale
Traceback (most recent call last):
  File "/Users/ogahserge/Documents/smitci/venv/lib/python3.9/site-packages/django/contrib/sessions/backends/base.py", line 187, in _get_session
    return self._session_cache
AttributeError: 'SessionStore' object has no attribute '_session_cache'

During handling of the above exception, another exception occurred:

Traceback (most recent call last):
  File "/Users/ogahserge/Documents/smitci/venv/lib/python3.9/site-packages/django/db/backends/utils.py", line 89, in _execute
    return self.cursor.execute(sql, params)
psycopg2.errors.UndefinedTable: relation "django_session" does not exist
LINE 1: ...ession_data", "django_session"."expire_date" FROM "django_se...
                                                             ^


The above exception was the direct cause of the following exception:

Traceback (most recent call last):
  File "/Users/ogahserge/Documents/smitci/venv/lib/python3.9/site-packages/asgiref/sync.py", line 518, in thread_handler
    raise exc_info[1]
  File "/Users/ogahserge/Documents/smitci/venv/lib/python3.9/site-packages/django/core/handlers/exception.py", line 42, in inner
    response = await get_response(request)
  File "/Users/ogahserge/Documents/smitci/venv/lib/python3.9/site-packages/django/core/handlers/base.py", line 253, in _get_response_async
    response = await wrapped_callback(
  File "/Users/ogahserge/Documents/smitci/venv/lib/python3.9/site-packages/asgiref/sync.py", line 468, in __call__
    ret = await asyncio.shield(exec_coro)
  File "/Applications/Xcode.app/Contents/Developer/Library/Frameworks/Python3.framework/Versions/3.9/lib/python3.9/concurrent/futures/thread.py", line 52, in run
    result = self.fn(*self.args, **self.kwargs)
  File "/Users/ogahserge/Documents/smitci/venv/lib/python3.9/site-packages/asgiref/sync.py", line 522, in thread_handler
    return func(*args, **kwargs)
  File "/Users/ogahserge/Documents/smitci/venv/lib/python3.9/site-packages/django/views/generic/base.py", line 104, in view
    return self.dispatch(request, *args, **kwargs)
  File "/Users/ogahserge/Documents/smitci/venv/lib/python3.9/site-packages/django/contrib/auth/mixins.py", line 71, in dispatch
    if not request.user.is_authenticated:
  File "/Users/ogahserge/Documents/smitci/venv/lib/python3.9/site-packages/django/utils/functional.py", line 266, in inner
    self._setup()
  File "/Users/ogahserge/Documents/smitci/venv/lib/python3.9/site-packages/django/utils/functional.py", line 419, in _setup
    self._wrapped = self._setupfunc()
  File "/Users/ogahserge/Documents/smitci/venv/lib/python3.9/site-packages/django/contrib/auth/middleware.py", line 25, in <lambda>
    request.user = SimpleLazyObject(lambda: get_user(request))
  File "/Users/ogahserge/Documents/smitci/venv/lib/python3.9/site-packages/django/contrib/auth/middleware.py", line 11, in get_user
    request._cached_user = auth.get_user(request)
  File "/Users/ogahserge/Documents/smitci/venv/lib/python3.9/site-packages/django/contrib/auth/__init__.py", line 191, in get_user
    user_id = _get_user_session_key(request)
  File "/Users/ogahserge/Documents/smitci/venv/lib/python3.9/site-packages/django/contrib/auth/__init__.py", line 60, in _get_user_session_key
    return get_user_model()._meta.pk.to_python(request.session[SESSION_KEY])
  File "/Users/ogahserge/Documents/smitci/venv/lib/python3.9/site-packages/django/contrib/sessions/backends/base.py", line 53, in __getitem__
    return self._session[key]
  File "/Users/ogahserge/Documents/smitci/venv/lib/python3.9/site-packages/django/contrib/sessions/backends/base.py", line 192, in _get_session
    self._session_cache = self.load()
  File "/Users/ogahserge/Documents/smitci/venv/lib/python3.9/site-packages/django/contrib/sessions/backends/db.py", line 42, in load
    s = self._get_session_from_db()
  File "/Users/ogahserge/Documents/smitci/venv/lib/python3.9/site-packages/django/contrib/sessions/backends/db.py", line 32, in _get_session_from_db
    return self.model.objects.get(
  File "/Users/ogahserge/Documents/smitci/venv/lib/python3.9/site-packages/django/db/models/manager.py", line 87, in manager_method
    return getattr(self.get_queryset(), name)(*args, **kwargs)
  File "/Users/ogahserge/Documents/smitci/venv/lib/python3.9/site-packages/django/db/models/query.py", line 633, in get
    num = len(clone)
  File "/Users/ogahserge/Documents/smitci/venv/lib/python3.9/site-packages/django/db/models/query.py", line 380, in __len__
    self._fetch_all()
  File "/Users/ogahserge/Documents/smitci/venv/lib/python3.9/site-packages/django/db/models/query.py", line 1881, in _fetch_all
    self._result_cache = list(self._iterable_class(self))
  File "/Users/ogahserge/Documents/smitci/venv/lib/python3.9/site-packages/django/db/models/query.py", line 91, in __iter__
    results = compiler.execute_sql(
  File "/Users/ogahserge/Documents/smitci/venv/lib/python3.9/site-packages/django/db/models/sql/compiler.py", line 1562, in execute_sql
    cursor.execute(sql, params)
  File "/Users/ogahserge/Documents/smitci/venv/lib/python3.9/site-packages/django/db/backends/utils.py", line 102, in execute
    return super().execute(sql, params)
  File "/Users/ogahserge/Documents/smitci/venv/lib/python3.9/site-packages/django/db/backends/utils.py", line 67, in execute
    return self._execute_with_wrappers(
  File "/Users/ogahserge/Documents/smitci/venv/lib/python3.9/site-packages/django/db/backends/utils.py", line 80, in _execute_with_wrappers
    return executor(sql, params, many, context)
  File "/Users/ogahserge/Documents/smitci/venv/lib/python3.9/site-packages/django/db/backends/utils.py", line 89, in _execute
    return self.cursor.execute(sql, params)
  File "/Users/ogahserge/Documents/smitci/venv/lib/python3.9/site-packages/django/db/utils.py", line 91, in __exit__
    raise dj_exc_value.with_traceback(traceback) from exc_value
  File "/Users/ogahserge/Documents/smitci/venv/lib/python3.9/site-packages/django/db/backends/utils.py", line 89, in _execute
    return self.cursor.execute(sql, params)
django.db.utils.ProgrammingError: relation "django_session" does not exist
LINE 1: ...ession_data", "django_session"."expire_date" FROM "django_se...
                                                             ^

[35;1mHTTP GET /hospitalisation/generale 500 [0.09, 127.0.0.1:59662][0m
Internal Server Error: /hospitalisation/generale
Traceback (most recent call last):
  File "/Users/ogahserge/Documents/smitci/venv/lib/python3.9/site-packages/django/contrib/sessions/backends/base.py", line 187, in _get_session
    return self._session_cache
AttributeError: 'SessionStore' object has no attribute '_session_cache'

During handling of the above exception, another exception occurred:

Traceback (most recent call last):
  File "/Users/ogahserge/Documents/smitci/venv/lib/python3.9/site-packages/django/db/backends/utils.py", line 89, in _execute
    return self.cursor.execute(sql, params)
psycopg2.errors.UndefinedTable: relation "django_session" does not exist
LINE 1: ...ession_data", "django_session"."expire_date" FROM "django_se...
                                                             ^


The above exception was the direct cause of the following exception:

Traceback (most recent call last):
  File "/Users/ogahserge/Documents/smitci/venv/lib/python3.9/site-packages/asgiref/sync.py", line 518, in thread_handler
    raise exc_info[1]
  File "/Users/ogahserge/Documents/smitci/venv/lib/python3.9/site-packages/django/core/handlers/exception.py", line 42, in inner
    response = await get_response(request)
  File "/Users/ogahserge/Documents/smitci/venv/lib/python3.9/site-packages/django/core/handlers/base.py", line 253, in _get_response_async
    response = await wrapped_callback(
  File "/Users/ogahserge/Documents/smitci/venv/lib/python3.9/site-packages/asgiref/sync.py", line 468, in __call__
    ret = await asyncio.shield(exec_coro)
  File "/Applications/Xcode.app/Contents/Developer/Library/Frameworks/Python3.framework/Versions/3.9/lib/python3.9/concurrent/futures/thread.py", line 52, in run
    result = self.fn(*self.args, **self.kwargs)
  File "/Users/ogahserge/Documents/smitci/venv/lib/python3.9/site-packages/asgiref/sync.py", line 522, in thread_handler
    return func(*args, **kwargs)
  File "/Users/ogahserge/Documents/smitci/venv/lib/python3.9/site-packages/django/views/generic/base.py", line 104, in view
    return self.dispatch(request, *args, **kwargs)
  File "/Users/ogahserge/Documents/smitci/venv/lib/python3.9/site-packages/django/contrib/auth/mixins.py", line 71, in dispatch
    if not request.user.is_authenticated:
  File "/Users/ogahserge/Documents/smitci/venv/lib/python3.9/site-packages/django/utils/functional.py", line 266, in inner
    self._setup()
  File "/Users/ogahserge/Documents/smitci/venv/lib/python3.9/site-packages/django/utils/functional.py", line 419, in _setup
    self._wrapped = self._setupfunc()
  File "/Users/ogahserge/Documents/smitci/venv/lib/python3.9/site-packages/django/contrib/auth/middleware.py", line 25, in <lambda>
    request.user = SimpleLazyObject(lambda: get_user(request))
  File "/Users/ogahserge/Documents/smitci/venv/lib/python3.9/site-packages/django/contrib/auth/middleware.py", line 11, in get_user
    request._cached_user = auth.get_user(request)
  File "/Users/ogahserge/Documents/smitci/venv/lib/python3.9/site-packages/django/contrib/auth/__init__.py", line 191, in get_user
    user_id = _get_user_session_key(request)
  File "/Users/ogahserge/Documents/smitci/venv/lib/python3.9/site-packages/django/contrib/auth/__init__.py", line 60, in _get_user_session_key
    return get_user_model()._meta.pk.to_python(request.session[SESSION_KEY])
  File "/Users/ogahserge/Documents/smitci/venv/lib/python3.9/site-packages/django/contrib/sessions/backends/base.py", line 53, in __getitem__
    return self._session[key]
  File "/Users/ogahserge/Documents/smitci/venv/lib/python3.9/site-packages/django/contrib/sessions/backends/base.py", line 192, in _get_session
    self._session_cache = self.load()
  File "/Users/ogahserge/Documents/smitci/venv/lib/python3.9/site-packages/django/contrib/sessions/backends/db.py", line 42, in load
    s = self._get_session_from_db()
  File "/Users/ogahserge/Documents/smitci/venv/lib/python3.9/site-packages/django/contrib/sessions/backends/db.py", line 32, in _get_session_from_db
    return self.model.objects.get(
  File "/Users/ogahserge/Documents/smitci/venv/lib/python3.9/site-packages/django/db/models/manager.py", line 87, in manager_method
    return getattr(self.get_queryset(), name)(*args, **kwargs)
  File "/Users/ogahserge/Documents/smitci/venv/lib/python3.9/site-packages/django/db/models/query.py", line 633, in get
    num = len(clone)
  File "/Users/ogahserge/Documents/smitci/venv/lib/python3.9/site-packages/django/db/models/query.py", line 380, in __len__
    self._fetch_all()
  File "/Users/ogahserge/Documents/smitci/venv/lib/python3.9/site-packages/django/db/models/query.py", line 1881, in _fetch_all
    self._result_cache = list(self._iterable_class(self))
  File "/Users/ogahserge/Documents/smitci/venv/lib/python3.9/site-packages/django/db/models/query.py", line 91, in __iter__
    results = compiler.execute_sql(
  File "/Users/ogahserge/Documents/smitci/venv/lib/python3.9/site-packages/django/db/models/sql/compiler.py", line 1562, in execute_sql
    cursor.execute(sql, params)
  File "/Users/ogahserge/Documents/smitci/venv/lib/python3.9/site-packages/django/db/backends/utils.py", line 102, in execute
    return super().execute(sql, params)
  File "/Users/ogahserge/Documents/smitci/venv/lib/python3.9/site-packages/django/db/backends/utils.py", line 67, in execute
    return self._execute_with_wrappers(
  File "/Users/ogahserge/Documents/smitci/venv/lib/python3.9/site-packages/django/db/backends/utils.py", line 80, in _execute_with_wrappers
    return executor(sql, params, many, context)
  File "/Users/ogahserge/Documents/smitci/venv/lib/python3.9/site-packages/django/db/backends/utils.py", line 89, in _execute
    return self.cursor.execute(sql, params)
  File "/Users/ogahserge/Documents/smitci/venv/lib/python3.9/site-packages/django/db/utils.py", line 91, in __exit__
    raise dj_exc_value.with_traceback(traceback) from exc_value
  File "/Users/ogahserge/Documents/smitci/venv/lib/python3.9/site-packages/django/db/backends/utils.py", line 89, in _execute
    return self.cursor.execute(sql, params)
django.db.utils.ProgrammingError: relation "django_session" does not exist
LINE 1: ...ession_data", "django_session"."expire_date" FROM "django_se...
                                                             ^

[35;1mHTTP GET /hospitalisation/generale 500 [0.06, 127.0.0.1:59662][0m
