Internal Server Error: /
Traceback (most recent call last):
  File "/Users/ogahserge/Documents/smitci/venv/lib/python3.9/site-packages/asgiref/sync.py", line 518, in thread_handler
    raise exc_info[1]
  File "/Users/ogahserge/Documents/smitci/venv/lib/python3.9/site-packages/django/core/handlers/exception.py", line 42, in inner
    response = await get_response(request)
  File "/Users/ogahserge/Documents/smitci/venv/lib/python3.9/site-packages/django/core/handlers/base.py", line 284, in _get_response_async
    response = await sync_to_async(
  File "/Users/ogahserge/Documents/smitci/venv/lib/python3.9/site-packages/asgiref/sync.py", line 468, in __call__
    ret = await asyncio.shield(exec_coro)
  File "/Users/ogahserge/Documents/smitci/venv/lib/python3.9/site-packages/asgiref/current_thread_executor.py", line 40, in run
    result = self.fn(*self.args, **self.kwargs)
  File "/Users/ogahserge/Documents/smitci/venv/lib/python3.9/site-packages/asgiref/sync.py", line 522, in thread_handler
    return func(*args, **kwargs)
  File "/Users/ogahserge/Documents/smitci/venv/lib/python3.9/site-packages/django/template/response.py", line 114, in render
    self.content = self.rendered_content
  File "/Users/ogahserge/Documents/smitci/venv/lib/python3.9/site-packages/django/template/response.py", line 90, in rendered_content
    template = self.resolve_template(self.template_name)
  File "/Users/ogahserge/Documents/smitci/venv/lib/python3.9/site-packages/django/template/response.py", line 72, in resolve_template
    return select_template(template, using=self.using)
  File "/Users/ogahserge/Documents/smitci/venv/lib/python3.9/site-packages/django/template/loader.py", line 47, in select_template
    raise TemplateDoesNotExist(", ".join(template_name_list), chain=chain)
django.template.exceptions.TemplateDoesNotExist: pages/home.html
[35;1mHTTP GET / 500 [0.12, 127.0.0.1:51907][0m
Internal Server Error: /
Traceback (most recent call last):
  File "/Users/ogahserge/Documents/smitci/venv/lib/python3.9/site-packages/asgiref/sync.py", line 518, in thread_handler
    raise exc_info[1]
  File "/Users/ogahserge/Documents/smitci/venv/lib/python3.9/site-packages/django/core/handlers/exception.py", line 42, in inner
    response = await get_response(request)
  File "/Users/ogahserge/Documents/smitci/venv/lib/python3.9/site-packages/django/core/handlers/base.py", line 284, in _get_response_async
    response = await sync_to_async(
  File "/Users/ogahserge/Documents/smitci/venv/lib/python3.9/site-packages/asgiref/sync.py", line 468, in __call__
    ret = await asyncio.shield(exec_coro)
  File "/Users/ogahserge/Documents/smitci/venv/lib/python3.9/site-packages/asgiref/current_thread_executor.py", line 40, in run
    result = self.fn(*self.args, **self.kwargs)
  File "/Users/ogahserge/Documents/smitci/venv/lib/python3.9/site-packages/asgiref/sync.py", line 522, in thread_handler
    return func(*args, **kwargs)
  File "/Users/ogahserge/Documents/smitci/venv/lib/python3.9/site-packages/django/template/response.py", line 114, in render
    self.content = self.rendered_content
  File "/Users/ogahserge/Documents/smitci/venv/lib/python3.9/site-packages/django/template/response.py", line 90, in rendered_content
    template = self.resolve_template(self.template_name)
  File "/Users/ogahserge/Documents/smitci/venv/lib/python3.9/site-packages/django/template/response.py", line 72, in resolve_template
    return select_template(template, using=self.using)
  File "/Users/ogahserge/Documents/smitci/venv/lib/python3.9/site-packages/django/template/loader.py", line 47, in select_template
    raise TemplateDoesNotExist(", ".join(template_name_list), chain=chain)
django.template.exceptions.TemplateDoesNotExist: pages/home.html
[35;1mHTTP GET / 500 [4.01, 127.0.0.1:52128][0m
Internal Server Error: /
Traceback (most recent call last):
  File "/Users/ogahserge/Documents/smitci/venv/lib/python3.9/site-packages/django/core/handlers/exception.py", line 55, in inner
    response = get_response(request)
  File "/Users/ogahserge/Documents/smitci/smit/middlewares.py", line 23, in __call__
    if now - last_activity_time > timedelta(seconds=settings.SESSION_COOKIE_AGE):
AttributeError: module 'smitci.settings' has no attribute 'SESSION_COOKIE_AGE'
[35;1mHTTP GET / 500 [0.36, 127.0.0.1:52187][0m
Internal Server Error: /
Traceback (most recent call last):
  File "/Users/ogahserge/Documents/smitci/venv/lib/python3.9/site-packages/django/core/handlers/exception.py", line 55, in inner
    response = get_response(request)
  File "/Users/ogahserge/Documents/smitci/smit/middlewares.py", line 23, in __call__
    if now - last_activity_time > timedelta(seconds=settings.SESSION_COOKIE_AGE):
AttributeError: module 'smitci.settings' has no attribute 'SESSION_COOKIE_AGE'
[35;1mHTTP GET / 500 [0.08, 127.0.0.1:52190][0m
Internal Server Error: /
Traceback (most recent call last):
  File "/Users/ogahserge/Documents/smitci/venv/lib/python3.9/site-packages/django/core/handlers/exception.py", line 55, in inner
    response = get_response(request)
  File "/Users/ogahserge/Documents/smitci/smit/middlewares.py", line 23, in __call__
    if now - last_activity_time > timedelta(seconds=settings.SESSION_COOKIE_AGE):
AttributeError: module 'smitci.settings' has no attribute 'SESSION_COOKIE_AGE'
Internal Server Error: /
Traceback (most recent call last):
  File "/Users/ogahserge/Documents/smitci/venv/lib/python3.9/site-packages/django/core/handlers/exception.py", line 55, in inner
    response = get_response(request)
  File "/Users/ogahserge/Documents/smitci/smit/middlewares.py", line 23, in __call__
    if now - last_activity_time > timedelta(seconds=settings.SESSION_COOKIE_AGE):
AttributeError: module 'smitci.settings' has no attribute 'SESSION_COOKIE_AGE'
[35;1mHTTP GET / 500 [0.54, 127.0.0.1:52210][0m
Internal Server Error: /
Traceback (most recent call last):
  File "/Users/ogahserge/Documents/smitci/venv/lib/python3.9/site-packages/asgiref/sync.py", line 518, in thread_handler
    raise exc_info[1]
  File "/Users/ogahserge/Documents/smitci/venv/lib/python3.9/site-packages/django/core/handlers/exception.py", line 42, in inner
    response = await get_response(request)
  File "/Users/ogahserge/Documents/smitci/venv/lib/python3.9/site-packages/django/core/handlers/base.py", line 284, in _get_response_async
    response = await sync_to_async(
  File "/Users/ogahserge/Documents/smitci/venv/lib/python3.9/site-packages/asgiref/sync.py", line 468, in __call__
    ret = await asyncio.shield(exec_coro)
  File "/Users/ogahserge/Documents/smitci/venv/lib/python3.9/site-packages/asgiref/current_thread_executor.py", line 40, in run
    result = self.fn(*self.args, **self.kwargs)
  File "/Users/ogahserge/Documents/smitci/venv/lib/python3.9/site-packages/asgiref/sync.py", line 522, in thread_handler
    return func(*args, **kwargs)
  File "/Users/ogahserge/Documents/smitci/venv/lib/python3.9/site-packages/django/template/response.py", line 114, in render
    self.content = self.rendered_content
  File "/Users/ogahserge/Documents/smitci/venv/lib/python3.9/site-packages/django/template/response.py", line 90, in rendered_content
    template = self.resolve_template(self.template_name)
  File "/Users/ogahserge/Documents/smitci/venv/lib/python3.9/site-packages/django/template/response.py", line 72, in resolve_template
    return select_template(template, using=self.using)
  File "/Users/ogahserge/Documents/smitci/venv/lib/python3.9/site-packages/django/template/loader.py", line 47, in select_template
    raise TemplateDoesNotExist(", ".join(template_name_list), chain=chain)
django.template.exceptions.TemplateDoesNotExist: pages/home.html
[35;1mHTTP GET / 500 [0.72, 127.0.0.1:52232][0m
Internal Server Error: /
Traceback (most recent call last):
  File "/Users/ogahserge/Documents/smitci/venv/lib/python3.9/site-packages/asgiref/sync.py", line 518, in thread_handler
    raise exc_info[1]
  File "/Users/ogahserge/Documents/smitci/venv/lib/python3.9/site-packages/django/core/handlers/exception.py", line 42, in inner
    response = await get_response(request)
  File "/Users/ogahserge/Documents/smitci/venv/lib/python3.9/site-packages/django/core/handlers/base.py", line 284, in _get_response_async
    response = await sync_to_async(
  File "/Users/ogahserge/Documents/smitci/venv/lib/python3.9/site-packages/asgiref/sync.py", line 468, in __call__
    ret = await asyncio.shield(exec_coro)
  File "/Users/ogahserge/Documents/smitci/venv/lib/python3.9/site-packages/asgiref/current_thread_executor.py", line 40, in run
    result = self.fn(*self.args, **self.kwargs)
  File "/Users/ogahserge/Documents/smitci/venv/lib/python3.9/site-packages/asgiref/sync.py", line 522, in thread_handler
    return func(*args, **kwargs)
  File "/Users/ogahserge/Documents/smitci/venv/lib/python3.9/site-packages/django/template/response.py", line 114, in render
    self.content = self.rendered_content
  File "/Users/ogahserge/Documents/smitci/venv/lib/python3.9/site-packages/django/template/response.py", line 90, in rendered_content
    template = self.resolve_template(self.template_name)
  File "/Users/ogahserge/Documents/smitci/venv/lib/python3.9/site-packages/django/template/response.py", line 72, in resolve_template
    return select_template(template, using=self.using)
  File "/Users/ogahserge/Documents/smitci/venv/lib/python3.9/site-packages/django/template/loader.py", line 47, in select_template
    raise TemplateDoesNotExist(", ".join(template_name_list), chain=chain)
django.template.exceptions.TemplateDoesNotExist: pages/home.html
[35;1mHTTP GET / 500 [0.88, 127.0.0.1:52278][0m
Internal Server Error: /employees/
Traceback (most recent call last):
  File "/Users/ogahserge/Documents/smitci/venv/lib/python3.9/site-packages/asgiref/sync.py", line 518, in thread_handler
    raise exc_info[1]
  File "/Users/ogahserge/Documents/smitci/venv/lib/python3.9/site-packages/django/core/handlers/exception.py", line 42, in inner
    response = await get_response(request)
  File "/Users/ogahserge/Documents/smitci/venv/lib/python3.9/site-packages/django/core/handlers/base.py", line 284, in _get_response_async
    response = await sync_to_async(
  File "/Users/ogahserge/Documents/smitci/venv/lib/python3.9/site-packages/asgiref/sync.py", line 468, in __call__
    ret = await asyncio.shield(exec_coro)
  File "/Users/ogahserge/Documents/smitci/venv/lib/python3.9/site-packages/asgiref/current_thread_executor.py", line 40, in run
    result = self.fn(*self.args, **self.kwargs)
  File "/Users/ogahserge/Documents/smitci/venv/lib/python3.9/site-packages/asgiref/sync.py", line 522, in thread_handler
    return func(*args, **kwargs)
  File "/Users/ogahserge/Documents/smitci/venv/lib/python3.9/site-packages/django/template/response.py", line 114, in render
    self.content = self.rendered_content
  File "/Users/ogahserge/Documents/smitci/venv/lib/python3.9/site-packages/django/template/response.py", line 92, in rendered_content
    return template.render(context, self._request)
  File "/Users/ogahserge/Documents/smitci/venv/lib/python3.9/site-packages/django/template/backends/django.py", line 61, in render
    return self.template.render(context)
  File "/Users/ogahserge/Documents/smitci/venv/lib/python3.9/site-packages/django/template/base.py", line 175, in render
    return self._render(context)
  File "/Users/ogahserge/Documents/smitci/venv/lib/python3.9/site-packages/django/template/base.py", line 167, in _render
    return self.nodelist.render(context)
  File "/Users/ogahserge/Documents/smitci/venv/lib/python3.9/site-packages/django/template/base.py", line 1005, in render
    return SafeString("".join([node.render_annotated(context) for node in self]))
  File "/Users/ogahserge/Documents/smitci/venv/lib/python3.9/site-packages/django/template/base.py", line 1005, in <listcomp>
    return SafeString("".join([node.render_annotated(context) for node in self]))
  File "/Users/ogahserge/Documents/smitci/venv/lib/python3.9/site-packages/django/template/base.py", line 966, in render_annotated
    return self.render(context)
  File "/Users/ogahserge/Documents/smitci/venv/lib/python3.9/site-packages/django/template/loader_tags.py", line 157, in render
    return compiled_parent._render(context)
  File "/Users/ogahserge/Documents/smitci/venv/lib/python3.9/site-packages/django/template/base.py", line 167, in _render
    return self.nodelist.render(context)
  File "/Users/ogahserge/Documents/smitci/venv/lib/python3.9/site-packages/django/template/base.py", line 1005, in render
    return SafeString("".join([node.render_annotated(context) for node in self]))
  File "/Users/ogahserge/Documents/smitci/venv/lib/python3.9/site-packages/django/template/base.py", line 1005, in <listcomp>
    return SafeString("".join([node.render_annotated(context) for node in self]))
  File "/Users/ogahserge/Documents/smitci/venv/lib/python3.9/site-packages/django/template/base.py", line 966, in render_annotated
    return self.render(context)
  File "/Users/ogahserge/Documents/smitci/venv/lib/python3.9/site-packages/django/template/loader_tags.py", line 63, in render
    result = block.nodelist.render(context)
  File "/Users/ogahserge/Documents/smitci/venv/lib/python3.9/site-packages/django/template/base.py", line 1005, in render
    return SafeString("".join([node.render_annotated(context) for node in self]))
  File "/Users/ogahserge/Documents/smitci/venv/lib/python3.9/site-packages/django/template/base.py", line 1005, in <listcomp>
    return SafeString("".join([node.render_annotated(context) for node in self]))
  File "/Users/ogahserge/Documents/smitci/venv/lib/python3.9/site-packages/django/template/base.py", line 966, in render_annotated
    return self.render(context)
  File "/Users/ogahserge/Documents/smitci/venv/lib/python3.9/site-packages/django/template/defaulttags.py", line 238, in render
    nodelist.append(node.render_annotated(context))
  File "/Users/ogahserge/Documents/smitci/venv/lib/python3.9/site-packages/django/template/base.py", line 966, in render_annotated
    return self.render(context)
  File "/Users/ogahserge/Documents/smitci/venv/lib/python3.9/site-packages/django/template/defaulttags.py", line 471, in render
    url = reverse(view_name, args=args, kwargs=kwargs, current_app=current_app)
  File "/Users/ogahserge/Documents/smitci/venv/lib/python3.9/site-packages/django/urls/base.py", line 88, in reverse
    return resolver._reverse_with_prefix(view, prefix, *args, **kwargs)
  File "/Users/ogahserge/Documents/smitci/venv/lib/python3.9/site-packages/django/urls/resolvers.py", line 828, in _reverse_with_prefix
    raise NoReverseMatch(msg)
django.urls.exceptions.NoReverseMatch: Reverse for 'admin_reset_password' not found. 'admin_reset_password' is not a valid view function or pattern name.
[35;1mHTTP GET /employees/ 500 [0.18, 127.0.0.1:53377][0m
Internal Server Error: /employees/121/reset-password/
Traceback (most recent call last):
  File "/Users/ogahserge/Documents/smitci/venv/lib/python3.9/site-packages/asgiref/sync.py", line 518, in thread_handler
    raise exc_info[1]
  File "/Users/ogahserge/Documents/smitci/venv/lib/python3.9/site-packages/django/core/handlers/exception.py", line 42, in inner
    response = await get_response(request)
  File "/Users/ogahserge/Documents/smitci/venv/lib/python3.9/site-packages/django/core/handlers/base.py", line 253, in _get_response_async
    response = await wrapped_callback(
  File "/Users/ogahserge/Documents/smitci/venv/lib/python3.9/site-packages/asgiref/sync.py", line 468, in __call__
    ret = await asyncio.shield(exec_coro)
  File "/Users/ogahserge/Documents/smitci/venv/lib/python3.9/site-packages/asgiref/current_thread_executor.py", line 40, in run
    result = self.fn(*self.args, **self.kwargs)
  File "/Users/ogahserge/Documents/smitci/venv/lib/python3.9/site-packages/asgiref/sync.py", line 522, in thread_handler
    return func(*args, **kwargs)
  File "/Users/ogahserge/Documents/smitci/venv/lib/python3.9/site-packages/django/views/generic/base.py", line 104, in view
    return self.dispatch(request, *args, **kwargs)
  File "/Users/ogahserge/Documents/smitci/venv/lib/python3.9/site-packages/django/contrib/auth/mixins.py", line 73, in dispatch
    return super().dispatch(request, *args, **kwargs)
  File "/Users/ogahserge/Documents/smitci/venv/lib/python3.9/site-packages/django/views/generic/base.py", line 143, in dispatch
    return handler(request, *args, **kwargs)
  File "/Users/ogahserge/Documents/smitci/venv/lib/python3.9/site-packages/django/views/generic/edit.py", line 153, in post
    return self.form_valid(form)
  File "/Users/ogahserge/Documents/smitci/core/views.py", line 346, in form_valid
    self._send_password_change_notification(user)
  File "/Users/ogahserge/Documents/smitci/core/views.py", line 379, in _send_password_change_notification
    L'équipe {settings.SITE_NAME}
NameError: name 'settings' is not defined
[35;1mHTTP POST /employees/121/reset-password/ 500 [0.29, 127.0.0.1:53791][0m
Internal Server Error: /employees/121/reset-password/
Traceback (most recent call last):
  File "/Users/ogahserge/Documents/smitci/venv/lib/python3.9/site-packages/asgiref/sync.py", line 518, in thread_handler
    raise exc_info[1]
  File "/Users/ogahserge/Documents/smitci/venv/lib/python3.9/site-packages/django/core/handlers/exception.py", line 42, in inner
    response = await get_response(request)
  File "/Users/ogahserge/Documents/smitci/venv/lib/python3.9/site-packages/django/core/handlers/base.py", line 253, in _get_response_async
    response = await wrapped_callback(
  File "/Users/ogahserge/Documents/smitci/venv/lib/python3.9/site-packages/asgiref/sync.py", line 468, in __call__
    ret = await asyncio.shield(exec_coro)
  File "/Users/ogahserge/Documents/smitci/venv/lib/python3.9/site-packages/asgiref/current_thread_executor.py", line 40, in run
    result = self.fn(*self.args, **self.kwargs)
  File "/Users/ogahserge/Documents/smitci/venv/lib/python3.9/site-packages/asgiref/sync.py", line 522, in thread_handler
    return func(*args, **kwargs)
  File "/Users/ogahserge/Documents/smitci/venv/lib/python3.9/site-packages/django/views/generic/base.py", line 104, in view
    return self.dispatch(request, *args, **kwargs)
  File "/Users/ogahserge/Documents/smitci/venv/lib/python3.9/site-packages/django/contrib/auth/mixins.py", line 73, in dispatch
    return super().dispatch(request, *args, **kwargs)
  File "/Users/ogahserge/Documents/smitci/venv/lib/python3.9/site-packages/django/views/generic/base.py", line 143, in dispatch
    return handler(request, *args, **kwargs)
  File "/Users/ogahserge/Documents/smitci/venv/lib/python3.9/site-packages/django/views/generic/edit.py", line 153, in post
    return self.form_valid(form)
  File "/Users/ogahserge/Documents/smitci/core/views.py", line 347, in form_valid
    self._send_password_change_notification(user)
  File "/Users/ogahserge/Documents/smitci/core/views.py", line 380, in _send_password_change_notification
    L'équipe {settings.SITE_NAME}
  File "/Users/ogahserge/Documents/smitci/venv/lib/python3.9/site-packages/django/conf/__init__.py", line 104, in __getattr__
    val = getattr(_wrapped, name)
AttributeError: 'Settings' object has no attribute 'SITE_NAME'
[35;1mHTTP POST /employees/121/reset-password/ 500 [0.42, 127.0.0.1:53819][0m
Internal Server Error: /employees/121/reset-password/
Traceback (most recent call last):
  File "/Users/ogahserge/Documents/smitci/venv/lib/python3.9/site-packages/django/core/mail/message.py", line 86, in sanitize_address
    token, rest = parser.get_mailbox(addr)
  File "/Applications/Xcode.app/Contents/Developer/Library/Frameworks/Python3.framework/Versions/3.9/lib/python3.9/email/_header_value_parser.py", line 1791, in get_mailbox
    token, value = get_name_addr(value)
  File "/Applications/Xcode.app/Contents/Developer/Library/Frameworks/Python3.framework/Versions/3.9/lib/python3.9/email/_header_value_parser.py", line 1760, in get_name_addr
    if value[0] in CFWS_LEADER:
IndexError: string index out of range

During handling of the above exception, another exception occurred:

Traceback (most recent call last):
  File "/Users/ogahserge/Documents/smitci/core/views.py", line 381, in _send_password_change_notification
    send_mail(
  File "/Users/ogahserge/Documents/smitci/venv/lib/python3.9/site-packages/django/core/mail/__init__.py", line 87, in send_mail
    return mail.send()
  File "/Users/ogahserge/Documents/smitci/venv/lib/python3.9/site-packages/django/core/mail/message.py", line 299, in send
    return self.get_connection(fail_silently).send_messages([self])
  File "/Users/ogahserge/Documents/smitci/venv/lib/python3.9/site-packages/django/core/mail/backends/smtp.py", line 134, in send_messages
    sent = self._send(message)
  File "/Users/ogahserge/Documents/smitci/venv/lib/python3.9/site-packages/django/core/mail/backends/smtp.py", line 146, in _send
    from_email = sanitize_address(email_message.from_email, encoding)
  File "/Users/ogahserge/Documents/smitci/venv/lib/python3.9/site-packages/django/core/mail/message.py", line 88, in sanitize_address
    raise ValueError('Invalid address "%s"' % addr)
ValueError: Invalid address ""

During handling of the above exception, another exception occurred:

Traceback (most recent call last):
  File "/Users/ogahserge/Documents/smitci/venv/lib/python3.9/site-packages/asgiref/sync.py", line 518, in thread_handler
    raise exc_info[1]
  File "/Users/ogahserge/Documents/smitci/venv/lib/python3.9/site-packages/django/core/handlers/exception.py", line 42, in inner
    response = await get_response(request)
  File "/Users/ogahserge/Documents/smitci/venv/lib/python3.9/site-packages/django/core/handlers/base.py", line 253, in _get_response_async
    response = await wrapped_callback(
  File "/Users/ogahserge/Documents/smitci/venv/lib/python3.9/site-packages/asgiref/sync.py", line 468, in __call__
    ret = await asyncio.shield(exec_coro)
  File "/Users/ogahserge/Documents/smitci/venv/lib/python3.9/site-packages/asgiref/current_thread_executor.py", line 40, in run
    result = self.fn(*self.args, **self.kwargs)
  File "/Users/ogahserge/Documents/smitci/venv/lib/python3.9/site-packages/asgiref/sync.py", line 522, in thread_handler
    return func(*args, **kwargs)
  File "/Users/ogahserge/Documents/smitci/venv/lib/python3.9/site-packages/django/views/generic/base.py", line 104, in view
    return self.dispatch(request, *args, **kwargs)
  File "/Users/ogahserge/Documents/smitci/venv/lib/python3.9/site-packages/django/contrib/auth/mixins.py", line 73, in dispatch
    return super().dispatch(request, *args, **kwargs)
  File "/Users/ogahserge/Documents/smitci/venv/lib/python3.9/site-packages/django/views/generic/base.py", line 143, in dispatch
    return handler(request, *args, **kwargs)
  File "/Users/ogahserge/Documents/smitci/venv/lib/python3.9/site-packages/django/views/generic/edit.py", line 153, in post
    return self.form_valid(form)
  File "/Users/ogahserge/Documents/smitci/core/views.py", line 347, in form_valid
    self._send_password_change_notification(user)
  File "/Users/ogahserge/Documents/smitci/core/views.py", line 389, in _send_password_change_notification
    logger.error(f"Erreur lors de l'envoi de la notification: {str(e)}")
NameError: name 'logger' is not defined
[35;1mHTTP POST /employees/121/reset-password/ 500 [1.62, 127.0.0.1:53871][0m
